Workbook

Sheet Login
A1: TC-ID | B1: Description (Test Scenario) | C1: Pre-condition | D1: Test step | E1: Step condition to perform | F1: Data | G1: Priority | H1: Expected result | I1: Testing Result | K1: Date | L1: Who checked | M1: BUG ID | N1: Comment
I2: Chrome | J2: Microsoft Edge
A3: Login-001 | B3: Login successful | C3: Remain on the Login screen | D3: 1. Input valid Email 2. Input valid Password 3. Click Login button | F3: Email: "test@gmail.com" Password: "123456" | G3: High | H3: Navigate to home page | I3: Passed | J3: Passed
A4: Login-002 | E4: 1.1 Input a valid Email address with leading and/or trailing spaces | F4: Email: " test@gmail.com " | G4: Medium | H4: The system automatically trims the extra spaces from the email address and logs the user in successfully. | I4: Passed | J4: Passed
A5: Login-003 | E5: 1.2 Input email uppercase/lowercase | F5: Email: "TEST@gmail.com" | G5: Low | H5: The system treats the email as case-insensitive and logs in successfully. | I5: Passed | J5: Passed
A6: Login-004 | B6: Login unsuccessful by Email | C6: Remain on the Login screen | D6: 1. Input invalid Email 2. Input valid Password 3. Click Login button | E6: 1.1 Leave Email empty | F6: Email: " " | G6: Medium | H6: Show message "Please enter your email." | I6: Passed | J6: Passed
A7: Login-005 | E7: 1.2 Input unregistered email | F7: Email: "abc@gmail.com" | G7: High | H7: Show message "Login was unsuccessful." | I7: Passed | J7: Passed
A8: Login-006 | E8: 1.3 Email without '@' | F8: Email: "abcgmail.com" | G8: Low | H8: Show message "Please enter a valid email address." | I8: Passed | J8: Passed
A9: Login-007 | E9: 1.4 Email contains space | F9: Email: "abc @gmail.com" | G9: High | H9: Show message "Please enter a valid email address." | I9: Un-test | J9: Un-test
A10: Login-008 | E10: 1.5 Input email exceeding maximum length | F10: Email: "verylongemail@gmail.com" | G10: Low | H10: Show message "Email must not exceed the maximum length." | I10: Failed | J10: Failed
A11: Login-009 | E11: 1.6 Input email containing "#" | F11: Email: "abc#@gmail.com" | G11: Low | H11: Show message "Please enter a valid email address." | I11: Failed | J11: Failed
A12: Login-010 | E12: 1.7 Email containing only '@' characters | F12: Email: "@" | G12: Low | H12: Show message "Please enter a valid email address." | I12: Passed | J12: Passed
A13: Login-011 | B13: Login unsuccessful by Password | C13: Remain on the Login screen | D13: 1. Input valid Email 2. Input invalid Password 3. Click Login button | E13: 2.1 Leave Password empty | F13: Password: " " | G13: Medium | H13: Show message "Please enter the password." | I13: Failed | J13: Failed | N13: The system shows a general error message instead of field-level validation.
A14: Login-012 | E14: 2.2 Input wrong password | F14: Password: "huyen" | G14: Medium | H14: Show message "Login was unsuccessful." | I14: Passed | J14: Passed
A15: Login-013 | E15: 2.3 Input password exceeding maximum length | F15: Password: "verylongpassword" | G15: Low | H15: Show message "Password must not exceed the maximum length." | I15: Failed | J15: Failed
A16: Login-014 | E16: 2.4 Input wrong password >3 times | F16: Password: "nhapqua3lan" | G16: High | H16: Show error message and lock the account after 3 failed login attempts. | I16: Failed | J16: Failed
A17: Login-015 | B17: Verify Enter key | C17: Remain on the Login screen | D17: 1. Input valid Email 2. Input valid Password 3. Press Enter | F17: Email: "test@gmail.com" Password: "123456" | G17: High | H17: Login success | I17: Passed | J17: Passed
A18: Login-016 | B18: Verify Remember Me | C18: Remain on the Login screen | D18: 1. Enter a valid Email and Password. 2. Check the "Remember me?" checkbox. 3. Click the "LOG IN" button. 4. Close the browser (or current tab). 5. | E18: 2.1 Check Remember Me | F18: Email: "test@gmail.com" Password: "123456" | G18: High | H18: Reopen the browser and navigate back to the nopCommerce website. | I18: Passed | J18: Passed
A19: Login-017 | B19: Login from Cart page | C19: Remain on the Cart screen | D19: 1. Click Checkout 2. Input valid Email 3. Input valid Password 4. Click Login button | E19: 1.1 Redirect to Login | F19: Email: "test@gmail.com" Password: "123456" | G19: High | H19: Login is successful and the user is redirected back to the Cart page. | I19: Passed | J19: Passed
A20: Login-018 | B20: Login unsuccessful with empty fields | C20: Remain on the Login screen | D20: 1. Leave Email empty 2. Leave Password empty 3. Click Login button | F20: Email: " " Password: " " | G20: High | H20: Show message "Please enter your email" | I20: Passed | J20: Passed
A21: Login-019 | B21: Verify Show/Hide password functionality (Eye icon) | C21: Remain on the Login screen | D21: 1. Input any characters into the Password field. 2. Click on the "Eye" icon inside the Password field. 3. Click on the "Eye" icon again. | F21: Password: "123456" | G21: High | H21: 2.1 The password characters (masked as dots) are displayed as plain text. 2.2 The password characters are masked again as dots (••••••). | I21: Passed | J21: Passed

Sheet Logout
A1: TC-ID | B1: Description (Test Scenario) | C1: Pre-condition | D1: Test step | E1: Step condition to perform | F1: Data | G1: Priority | H1: Expected result | I1: Testing Result | K1: Date | L1: Who checked | M1: BUG ID | N1: Comment
I2: Chrome | J2: Microsoft Egde
A3: Logout-001 | B3: Logout successful | C3: User is logged in | D3: 1. Click Logout button | G3: High | H3: "Redirect to homepage. 'Log in' & 'Register' replace 'Log out' & 'My account'." | I3: Passed | J3: Passed
A4: Logout-002 | B4: Access My Account after logout | C4: User is logged in | D4: 1. Copy the URL of 'My Account' page. 2. Click Logout button. 3. Paste the URL into browser and press Enter. | G4: High | H4: Redirect to Login page | I4: Passed | J4: Passed
A5: Logout-003 | B5: Logout then press Back | C5: User is logged in | D5: 1. Click Logout button. 2. Press Back button on the browser. | G5: Medium | H5: "Browser shows cached page. Any new action redirects to Login page." | I5: Passed | J5: Passed
A6: Logout-004 | B6: Logout one tab, check another tab | C6: User is logged in on two different tabs (Tab A and Tab B) | D6: 1. On Tab A, click Logout button. 2. Switch to Tab B and reload the page (or click any link). | G6: Medium | H6: Tab B redirects to Login page (or shows logged out state). | I6: Passed | J6: Passed

Sheet Forgot Password
A1: TC-ID | B1: Description (Test Scenario) | C1: Pre-condition | D1: Test step | E1: Step condition to perform | F1: Data | G1: Priority | H1: Expected result | I1: Testing Result | K1: Date | L1: Who checked | M1: BUG ID | N1: Comment
I2: Chrome | J2: Microsoft Egde
A3: ForgotPassword-001 | B3: Verify Forgot Password feature with valid email | C3: Remain on the Forgot Password screen | D3: 1. Input valid Email 2. Click Recover button | F3: Email: "test@gmail.com" | G3: High | H3: Show message "Email with instructions has been sent to you." | I3: Passed | J3: Passed
A4: ForgotPassword-002 | E4: 1.1 Input a valid Email address with leading and/or trailing spaces | F4: Email: " test@gmail.com " | G4: Medium | H4: Show message "System auto-trims spaces and shows success message." | I4: Passed | J4: Passed
A5: ForgotPassword-003 | E5: 1.2 Input email uppercase/lowercase | F5: Email: "TEST@gmail.com" | G5: Medium | H5: Show message "Email with instructions has been sent to you." | I5: Passed | J5: Passed
A6: ForgotPassword-004 | B6: Verify Forgot Password feature with invalid email | C6: Remain on the Login screen | D6: 1. Input invalid Email 2. Click Recover button | E6: 1.1 Input unregistered email | F6: Email: "abc@gmail.com" | G6: High | H6: Show message "Email not found." | I6: Passed | J6: Passed
A7: ForgotPassword-005 | E7: 1.2 Leave Email empty | F7: Email: " " | G7: Low | H7: Show message "Enter your email" | I7: Passed | J7: Passed
A8: ForgotPassword-006 | E8: 1.3 Email without '@' | F8: abcgmail.com | G8: Low | H8: Show message "Please enter a valid email address." | I8: Passed | J8: Passed
A9: ForgotPassword-007 | E9: 1.4 Email contains space | F9: abc @gmail.com | G9: Medium | H9: Show message "Please enter a valid email address." | I9: Un-test | J9: Un-test
A10: ForgotPassword-008 | B10: Open Forgot Password from Login | C10: Remain on the Login screen | D10: 1. Click Forgot Password | E10: 1.1 Click link Forgot Password | G10: Medium | H10: Navigate to Forgot page | I10: Passed | J10: Passed

Sheet My Account
A1: TC-ID | B1: Description (Test Scenario) | C1: Pre-condition | D1: Test step | E1: Step condition to perform | F1: Data | G1: Priority | H1: Expected result | I1: Testing Result | K1: Date | L1: Who checked | M1: BUG ID | N1: Comment
I2: Chrome | J2: Microsoft Egde
A3: MyAccount-001 | B3: Update info successfully | C3: Remain on Customer info page | D3: 1. Input valid data in required fields 2. Click SAVE | E3: All mandatory fields (*) are filled correctly | F3: FName: "QA" LName: "Test" Email: "qa@gmail.com" | G3: High | H3: Show message "The customer info has been updated successfully." | I3: Passed | J3: Passed
A4: MyAccount-002 | B4: Update info unsuccessfully | C4: Remain on Customer info page | D4: 1. Input data in required fields 3. Click SAVE | E4: 1.1 Leave mandatory First name empty | F4: FName: " " | G4: Medium | H4: Show message "First name is required." | I4: Passed | J4: Passed
A5: MyAccount-003 | E5: 1.2 Leave mandatory Last name empty | F5: LName: " " | G5: Low | H5: Show message "Last name is required." | I5: Passed | J5: Passed
A6: MyAccount-004 | E6: 1.3 Leave mandatory Email empty | F6: Email: " " | G6: Low | H6: Show message "Email is required." | I6: Passed | J6: Passed
A7: MyAccount-005 | E7: 1.5 Input email exceeding maximum length | F7: Email: "verylongemail@gmail.com" | G7: Low | H7: Show message "Email address is too long." | I7: Passed | J7: Passed
A8: MyAccount-006 | E8: 1.6 Input duplicated Email | F8: Email: "user2@gmail.com" | G8: Low | H8: Show message "The email address is already in use" | I8: Passed | J8: Passed
A9: MyAccount-007 | E9: 1.7 Input only spaces in First name | F9: FName: " " | G9: Low | H9: Show message "First name is required." | I9: Passed | J9: Passed
A10: MyAccount-008 | E10: 1.8 Input excessively long string in Company Name | F10: CompanyName: "inputverylong" | G10: Low | H10: Show message "String or binary data would be truncated. The statement has been terminated." | I10: Passed | J10: Passed
A11: MyAccount-009 | E11: 1.9 Input email containing "#" | F11: Email: "abc#@gmail.com" | G11: Low | H11: Show message "Please enter a valid email address." | I11: Failed | J11: Failed | N11: The customer info has been updated successfully.

Sheet Checkout
A1: TC-ID | B1: Description (Test Scenario) | C1: Pre-condition | D1: Test step | E1: Step condition to perform | F1: Data | G1: Priority | H1: Expected result | I1: Testing Result | K1: Date | L1: Who checked | M1: BUG ID | N1: Comment
I2: Chrome | J2: Microsoft Egde
A3: Checkout-001 | B3: Checkout successfully | C3: Remain on the Cart screen (with items) | D3: 1. Check T&C 2. Click Checkout 3. Input valid info (Step 1-5) 4. Click Confirm | G3: High | H3: Navigate to "Thank you" page and show Order Number. Cart is emptied. | I3: Passed | J3: Passed
A4: Checkout-002 | B4: Checkout unsuccessful by Pre-Checkout | C4: Remain on the Cart screen (with items) | D4: 1. Uncheck Terms and Conditions checkbox 2. Click Checkout button | E4: 1.1 Leave T&C unchecked | G4: High | H4: Show warning message prompting user to accept the terms. | I4: Passed | J4: Passed
A5: Checkout-003 | B5: Checkout unsuccessful by Billing Address (Step 1) | C5: Remain on Checkout screen (Step 1) | D5: 1. Input invalid Billing info 2. Click Continue button | E5: 1.1 Leave First name empty | F5: First name: " " | G5: Medium | H5: Show message "First name is required." | I5: Passed | J5: Passed
A6: Checkout-004 | E6: 1.2 Leave Last name empty | F6: Last name: " " | G6: High | H6: Show message "Last name is required." | I6: Passed | J6: Passed
A7: Checkout-005 | E7: 1.3 Leave Email empty | F7: Email: " " | G7: Medium | H7: Show message "Email is required." | I7: Passed | J7: Passed
A8: Checkout-006 | E8: 1.4 Input invalid Email format | F8: Email: "abcgmail.com" | G8: High | H8: Show message "Please enter a valid email address." | I8: Passed | J8: Passed
A9: Checkout-007 | E9: 1.5 Do not select a country | G9: Medium | H9: Show message "Country is required." | I9: Passed | J9: Passed
A10: Checkout-008 | E10: 1.6 Leave City empty | F10: City: " " | G10: High | H10: Show message "City is required" | I10: Passed | J10: Passed
A11: Checkout-009 | E11: 1.7 Leave Address 1 empty | F11: Address 1: " " | G11: Medium | H11: Show message "Street address is required." | I11: Passed | J11: Passed
A12: Checkout-010 | E12: 1.8 Input alphabetic characters in Zip | F12: Zip: "abc" | G12: Medium | H12: System shows error message "Zip code must be numeric". | I12: Failed | J12: Failed
A13: Checkout-011 | E13: 1.9 Input special characters in Zip | F13: Zip: "*&^" | G13: Medium | H13: System shows error message "Zip code must be numeric". | I13: Failed | J13: Failed
A14: Checkout-012 | E14: 1.10 Leave Zip/postal code empty | F14: Zip: " " | G14: Medium | H14: Show message "Zip / postal code is required" | I14: Passed | J14: Passed
A15: Checkout-013 | E15: 1.11 Input alphabetic characters in Phone | F15: Phone: "abcdef" | G15: Medium | H15: System shows error message "Phone number must contain only digits". | I15: Failed | J15: Failed
A16: Checkout-014 | E16: 1.12 Input special characters in Phone | F16: Phone: "!@#$%" | G16: Medium | H16: System shows error message "Invalid phone number format". | I16: Failed | J16: Failed
A17: Checkout-015 | E17: 1.13 Input invalid phone length (short/long) | F17: Phone: "12" or "0123456789123456" | G17: Medium | H17: System shows error message "Phone number must be between X and Y digits". | I17: Failed | J17: Failed
A18: Checkout-016 | E18: 1.14 Leave Phone empty | F18: Phone: " " | G18: Medium | H18: Show message "Phone is required." | I18: Passed | J18: Passed
A19: Checkout-017 | B19: Checkout unsuccessful by Payment Info (Step 5) | C19: Remain on Checkout screen (Step 5) | D19: 1. Select Credit Card 2. Input invalid CC info 3. Click Continue button | E19: 2.1 Leave Cardholder name empty | F19: Cardholder: " " | G19: High | H19: Show message "Cardholder name is required." | I19: Passed | J19: Passed
A20: Checkout-018 | E20: 2.2 Leave Card number empty | F20: Card number: " " | G20: Medium | H20: Show message "Card number is required." | I20: Failed | J20: Failed
A21: Checkout-019 | E21: 2.3 Input Credit Card number containing text | F21: Card number: "abc123!@" | G21: Medium | H21: Show message "Wrong card number" | I21: Passed | J21: Passed
A22: Checkout-020 | E22: 2.4 Input expired credit card | F22: Expiration date:: 01 / 2024 | G22: High | H22: Show message "Card is expired" | I22: Passed | J22: Passed
A23: Checkout-021 | E23: 2.5 Input invalid Credit Card (length) | F23: Credit Card: "12" | G23: High | H23: Show message "Wrong card code". | I23: Passed | J23: Passed
A24: Checkout-022 | B24: Verify dynamic flow and methods | C24: Remain on Checkout screen (Step 1) | D24: 1. Uncheck "Ship to same address" 2. Click Continue button | G24: High | H24: System navigates to Step 2 (Shipping address). | I24: Passed | J24: Passed
A25: Checkout-023 | C25: Remain on Checkout screen (Step 4) | D25: 1. Select dynamic payment method | E25: 1.1 Select "Check / Money Order" | G25: High | H25: Verify Step 5 changes to instruction message instead of credit card form. | I25: Passed | J25: Passed
A26: Checkout-024 | B26: Verify Optional (Step 1) | C26: Remain on Checkout screen (Step 1) | D26: 1. Input data 2. Click Continue | E26: 1.1 Leave Company empty | F26: Company: " " | G26: Medium | H26: System accepts and proceeds (Optional field). | I26: Passed | J26: Passed
A27: Checkout-025 | E27: 1.2 Input valid Company name | F27: Company: "QA Tester" | G27: Medium | H27: System accepts and proceeds. | I27: Passed | J27: Passed
A28: Checkout-026 | E28: 1.3 Input excessive string in Company | F28: Company: 256 chars | G28: Medium | H28: System shows length error. | I28: Failed | J28: Failed
A29: Checkout-027 | E29: 1.4 Leave Address 2 empty | F29: Address 2: " " | G29: Low | H29: System accepts and proceeds (Optional). | I29: Passed | J29: Passed
A30: Checkout-028 | E30: 1.5 Leave Fax empty | F30: Fax number:: " " | G30: Low | H30: System accepts and proceeds (Optional). | I30: Passed | J30: Passed
A31: Checkout-029 | E31: 1.6 Input alphabetic in Fax | F31: Fax number:: "abc" | G31: Medium | H31: System shows error "Invalid Fax format". | I31: Failed | J31: Failed
A32: Checkout-030 | E32: 1.7 Input 1 character in First Name | F32: First name: "A" | G32: Medium | H32: System accepts (Minimum boundary). | I32: Passed | J32: Passed
A33: Checkout-031 | E33: 1.8 Input only blank spaces in Last Name | F33: Last name: " " | G33: Medium | H33: System trims spaces and shows "Last name is required". | I33: Passed | J33: Passed
A34: Checkout-032 | E34: 1.9 Input numbers in City | F34: City: "12345" | G34: Medium | H34: System shows error message "City cannot contain numbers". | I34: Passed | J34: Passed
A35: Checkout-033 | B35: Verify Shipping Address Logic (Step 2) | C35: Remain on Checkout screen (Step 2) | D35: 1. Interact with address dropdown 2. Click Continue | E35: 1.1 Select existing address from dropdown | F35: Dropdown: Select index 1 | G35: High | H35: Form auto-fills with correct saved data. | I35: Passed | J35: Passed
A36: Checkout-034 | E36: 1.2 Select "New Address" from dropdown | F36: Dropdown: "New Address" | G36: High | H36: Form clears all fields for new input. | I36: Passed | J36: Passed
A37: Checkout-035 | E37: 1.3 Empty mandatory fields in Step 2 | F37: First name: " " | G37: High | H37: Show message "First name is required" at Step 2. | I37: Passed | J37: Passed
A38: Checkout-036 | B38: Verify Shipping Method options (Step 3) | C38: Remain on Checkout screen (Step 3) | D38: 1. Select radio button 2. Click Continue | E38: 1.1 Verify default selection | G38: Low | H38: "Ground ($0.00)" is selected by default. | I38: Passed | J38: Passed
A39: Checkout-037 | E39: 1.2 Select "Next Day Air" | G39: Medium | H39: Selection is highlighted. | I39: Passed | J39: Passed
A40: Checkout-038 | E40: 1.3 Select "2nd Day Air" | G40: Medium | H40: Selection is highlighted. | I40: Passed | J40: Passed
...

Sheet Summary 
A1: Name | B1: Total | C1: Chrome | F1: Microsoft Edge
C2: Passed | D2: Failed | E2: Un-test | F2: Passed | G2: Failed | H2: Un-test
A3: Login | B3: =COUNTIF(Login!A3:A99,"Login*") -> 19 | C3: =COUNTIF(Login!I3:I99,"Passed*") -> 13 | D3: =COUNTIF(Login!I3:I99,"Failed*") -> 5 | E3: =COUNTIF(Login!I3:I99,"Un-test*") -> 1 | F3: =COUNTIF(Login!J3:J99,"Passed*") -> 13 | G3: =COUNTIF(Login!J3:J98,"Failed*") -> 5 | H3: =COUNTIF(Login!J3:J98,"Un-test*") -> 1
A4: Logout | B4: =COUNTIF(Logout!A3:A27,"Logout*") -> 4 | C4: =COUNTIF(Logout!I3:I27,"Passed*") -> 4 | D4: =COUNTIF(Logout!I3:I27,"Failed*") -> 0 | E4: =COUNTIF(Logout!I3:I27,"Un-test*") -> 0 | F4: =COUNTIF(Logout!J3:J27,"Passed*") -> 4 | G4: =COUNTIF(Logout!J3:J27,"Failed*") -> 0 | H4: =COUNTIF(Logout!J3:J27,"Un-test*") -> 0
A5: Forgot Password | B5: =COUNTIF('Forgot Password'!A3:A29,"ForgotPassword*") -> 8 | C5: =COUNTIF('Forgot Password'!I3:I27,"Passed*") -> 7 | D5: =COUNTIF('Forgot Password'!I3:I27,"Failed*") -> 0 | E5: =COUNTIF('Forgot Password'!I3:I27,"Un-test*") -> 1 | F5: =COUNTIF('Forgot Password'!J3:J27,"Passed*") -> 7 | G5: =COUNTIF('Forgot Password'!J3:J27,"Failed*") -> 0 | H5: =COUNTIF('Forgot Password'!J3:J27,"Un-test*") -> 1
A6: My Account | B6: =COUNTIF('My Account'!A3:A30,"MyAccount*") -> 9 | C6: =COUNTIF('My Account'!I3:I27,"Passed*") -> 8 | D6: =COUNTIF('My Account'!I3:I27,"Failed*") -> 1 | E6: =COUNTIF('My Account'!I3:I27,"Un-test*") -> 0 | F6: =COUNTIF('My Account'!J3:J27,"Passed*") -> 8 | G6: =COUNTIF('My Account'!J3:J27,"Failed*") -> 1 | H6: =COUNTIF('My Account'!J3:J27,"Un-test*") -> 0
A7: Checkout | B7: =COUNTIF(Checkout!A3:A103,"Checkout*") -> 84 | C7: =COUNTIF(Checkout!I3:I103,"Passed*") -> 66 | D7: =COUNTIF(Checkout!I3:I103,"Failed*") -> 17 | E7: =COUNTIF(Checkout!I3:I103,"Un-test*") -> 1 | F7: =COUNTIF(Checkout!J3:J103,"Passed*") -> 66 | G7: =COUNTIF(Checkout!J3:J103,"Failed*") -> 17 | H7: =COUNTIF(Checkout!J3:J103,"Un-test*") -> 1
A8: Summary | B8: =SUM(B3:B7) -> 124 | C8: =SUM(C3:C7) -> 98 | D8: =SUM(D3:D7) -> 23 | E8: =SUM(E3:E7) -> 3 | F8: =SUM(F3:F7) -> 98 | G8: =SUM(G3:G7) -> 23 | H8: =SUM(H3:H7) -> 3
